import os

'''1
Traceback (most recent call last):
  File "/opt/conda/envs/python35-paddle120-env/lib/python3.7/site-packages/tensorflow_core/python/client/session.py", line 1365, in _do_call
    return fn(*args)
  File "/opt/conda/envs/python35-paddle120-env/lib/python3.7/site-packages/tensorflow_core/python/client/session.py", line 1350, in _run_fn
    target_list, run_metadata)
  File "/opt/conda/envs/python35-paddle120-env/lib/python3.7/site-packages/tensorflow_core/python/client/session.py", line 1443, in _call_tf_sessionrun
    run_metadata)
tensorflow.python.framework.errors_impl.InvalidArgumentError: indices[3550] = 201060 is not in [0, 4731)
         [[{{node training/lookup/embedding_lookup_1}}]]
'''

'''

'''